<?xml version="1.0" ?>
<!-- =================================================================================== -->
<!-- |    This document was autogenerated by xacro from leap_rx1.urdf.xacro            | -->
<!-- |    EDITING THIS FILE BY HAND IS NOT RECOMMENDED                                 | -->
<!-- =================================================================================== -->
<!--Note that the inertia values are placeholder and need to be updated for proper physics simulation-->
<robot name="rx1">
  <material name="red">
    <color rgba="1 0 0 1"/>
  </material>
  <material name="white">
    <color rgba="1 1 1 1"/>
  </material>
  <material name="blue">
    <color rgba="0 0 1 1"/>
  </material>
  <link name="base_link">
    <inertial>
      <mass value="5.0"/>
      <inertia ixx="0.1" ixy="0.0" ixz="0.0" iyy="0.04" iyz="0.0" izz="0.2"/>
    </inertial>
    <visual>
      <geometry>
        <mesh filename="package://rx1_description/meshes/base_link.stl"/>
      </geometry>
      <material name="white"/>
    </visual>
    <collision>
      <geometry>
        <mesh filename="package://rx1_description/meshes/base_link.stl"/>
      </geometry>
    </collision>
  </link>
  <!--                            TORSO START                         -->
  <link name="torso_yaw_link">
    <inertial>
      <mass value="5.0"/>
      <inertia ixx="1.0" ixy="0.0" ixz="0.0" iyy="1.0" iyz="0.0" izz="1.0"/>
    </inertial>
    <visual>
      <geometry>
        <mesh filename="package://rx1_description/meshes/torso_yaw_link.stl"/>
      </geometry>
      <origin rpy="0 0 0" xyz="0 0 0"/>
      <material name="white"/>
    </visual>
    <collision>
      <geometry>
        <mesh filename="package://rx1_description/meshes/torso_yaw_link.stl"/>
      </geometry>
      <origin rpy="0 0 0" xyz="0 0 0"/>
    </collision>
  </link>
  <joint name="base2torso_yaw_joint" type="revolute">
    <axis xyz="0 0 1"/>
    <limit effort="50.0" lower="-1.57075" upper="1.57075" velocity="15"/>
    <dynamics damping="0.5" friction="5.0"/>
    <origin rpy="0 0 0" xyz="0 0 0.5825"/>
    <parent link="base_link"/>
    <child link="torso_yaw_link"/>
  </joint>
  <link name="torso_pitch_link">
    <inertial>
      <mass value="0.5"/>
      <inertia ixx="1.0" ixy="0.0" ixz="0.0" iyy="1.0" iyz="0.0" izz="1.0"/>
    </inertial>
    <visual>
      <geometry>
        <cylinder length="0.03" radius="0.015"/>
      </geometry>
      <origin rpy="1.57075 0 0" xyz="0 0 0"/>
      <material name="blue"/>
    </visual>
    <collision>
      <geometry>
        <cylinder length="0.03" radius="0.01"/>
      </geometry>
      <origin rpy="1.57075 0 0" xyz="0 0 0"/>
    </collision>
  </link>
  <joint name="torso_yaw2pitch_joint" type="revolute">
    <axis xyz="0 1 0"/>
    <limit effort="50.0" lower="-0.785375" upper="0.785375" velocity="15"/>
    <dynamics damping="0.5" friction="0.1"/>
    <origin rpy="0 0 0" xyz="0 0 0.15"/>
    <parent link="torso_yaw_link"/>
    <child link="torso_pitch_link"/>
  </joint>
  <link name="torso_roll_link">
    <inertial>
      <mass value="0.5"/>
      <inertia ixx="1.0" ixy="0.0" ixz="0.0" iyy="1.0" iyz="0.0" izz="1.0"/>
    </inertial>
    <visual>
      <geometry>
        <cylinder length="0.03" radius="0.015"/>
      </geometry>
      <origin rpy="0 1.57075 0" xyz="0 0 0"/>
      <material name="red"/>
    </visual>
    <collision>
      <geometry>
        <cylinder length="0.03" radius="0.01"/>
      </geometry>
      <origin rpy="0 1.57075 0" xyz="0 0 0"/>
    </collision>
  </link>
  <joint name="torso_pitch2roll_joint" type="revolute">
    <axis xyz="1 0 0"/>
    <limit effort="50.0" lower="-0.785375" upper="0.785375" velocity="15"/>
    <dynamics damping="0.5" friction="0.1"/>
    <origin rpy="0 0 0" xyz="0 0 0"/>
    <parent link="torso_pitch_link"/>
    <child link="torso_roll_link"/>
  </joint>
  <link name="torso_link">
    <inertial>
      <mass value="1"/>
      <inertia ixx="4.16666667e-06" ixy="0.0" ixz="0.0" iyy="6.6666666667e-6" iyz="0.0" izz="04.16666667e-06"/>
    </inertial>
    <visual>
      <geometry>
        <!--box size="0.03 0.12 0.02" /-->
        <mesh filename="package://rx1_description/meshes/torso_link.stl"/>
      </geometry>
      <origin rpy="0 0 0" xyz="0 0 0"/>
      <material name="white"/>
    </visual>
    <collision>
      <geometry>
        <!--box size="0.03 0.12 0.02" /-->
        <mesh filename="package://rx1_description/meshes/torso_link.stl"/>
      </geometry>
      <origin rpy="0 0 0" xyz="0 0 0"/>
    </collision>
  </link>
  <joint name="torso_roll2torso_joint" type="fixed">
    <origin rpy="0 0 0" xyz="0 0 0.08"/>
    <parent link="torso_roll_link"/>
    <child link="torso_link"/>
  </joint>
  <!--                            TORSO END                         -->
  <!--                            HEAD START                        -->
  <link name="head_base_link">
    <inertial>
      <mass value="0.05"/>
      <inertia ixx="4.16666667e-06" ixy="0.0" ixz="0.0" iyy="6.6666666667e-6" iyz="0.0" izz="04.16666667e-06"/>
    </inertial>
    <visual>
      <geometry>
        <mesh filename="package://rx1_description/meshes/head/head_base_link.stl"/>
      </geometry>
      <origin rpy="0 0 0" xyz="0 0 0"/>
      <material name="white"/>
    </visual>
    <collision>
      <geometry>
        <mesh filename="package://rx1_description/meshes/head/head_base_link.stl"/>
      </geometry>
      <origin rpy="0 0 0" xyz="0 0 0"/>
    </collision>
  </link>
  <joint name="torso2head_base_joint" type="fixed">
    <origin rpy="0 0 0" xyz="0 0 0.21"/>
    <parent link="torso_link"/>
    <child link="head_base_link"/>
  </joint>
  <link name="neck_yaw_link">
    <inertial>
      <mass value="0.05"/>
      <inertia ixx="4.16666667e-06" ixy="0.0" ixz="0.0" iyy="6.6666666667e-6" iyz="0.0" izz="04.16666667e-06"/>
    </inertial>
    <visual>
      <geometry>
        <mesh filename="package://rx1_description/meshes/head/neck_yaw_link.stl"/>
      </geometry>
      <origin rpy="0 0 0" xyz="0 0 0"/>
      <material name="white"/>
    </visual>
    <collision>
      <geometry>
        <mesh filename="package://rx1_description/meshes/head/neck_yaw_link.stl"/>
      </geometry>
      <origin rpy="0 0 0" xyz="0 0 0"/>
    </collision>
  </link>
  <joint name="head_base2neck_yaw_joint" type="revolute">
    <axis xyz="0 0 1"/>
    <limit effort="50.0" lower="-1.57075" upper="1.57075" velocity="15"/>
    <dynamics damping="0.5" friction="0.1"/>
    <origin rpy="0 0 0" xyz="0 0 0"/>
    <parent link="head_base_link"/>
    <child link="neck_yaw_link"/>
  </joint>
  <link name="neck_pitch_link">
    <inertial>
      <mass value="0.05"/>
      <inertia ixx="4.16666667e-06" ixy="0.0" ixz="0.0" iyy="6.6666666667e-6" iyz="0.0" izz="04.16666667e-06"/>
    </inertial>
    <visual>
      <geometry>
        <mesh filename="package://rx1_description/meshes/head/neck_pitch_link.stl"/>
      </geometry>
      <origin rpy="0 0 0" xyz="0 0 0"/>
      <material name="white"/>
    </visual>
    <collision>
      <geometry>
        <mesh filename="package://rx1_description/meshes/head/neck_pitch_link.stl"/>
      </geometry>
      <origin rpy="0 0 0" xyz="0 0 0"/>
    </collision>
  </link>
  <joint name="neck_yaw2pitch_joint" type="revolute">
    <axis xyz="0 1 0"/>
    <limit effort="50.0" lower="-1.57075" upper="1.57075" velocity="15"/>
    <dynamics damping="0.5" friction="0.1"/>
    <origin rpy="0 0 0" xyz="0 0 0.035"/>
    <parent link="neck_yaw_link"/>
    <child link="neck_pitch_link"/>
  </joint>
  <link name="head_depth_cam_mount_link">
    <inertial>
      <mass value="0.05"/>
      <inertia ixx="4.16666667e-06" ixy="0.0" ixz="0.0" iyy="6.6666666667e-6" iyz="0.0" izz="04.16666667e-06"/>
    </inertial>
    <visual>
      <geometry>
        <mesh filename="package://rx1_description/meshes/head/head_depth_cam_mount_link.stl"/>
      </geometry>
      <origin rpy="0 0 0" xyz="0 0 0"/>
      <material name="white"/>
    </visual>
    <collision>
      <geometry>
        <mesh filename="package://rx1_description/meshes/head/head_depth_cam_mount_link.stl"/>
      </geometry>
      <origin rpy="0 0 0" xyz="0 0 0"/>
    </collision>
  </link>
  <joint name="neck_pitch2head_depth_cam_mount_joint" type="revolute">
    <axis xyz="1 0 0"/>
    <limit effort="50.0" lower="-1.57075" upper="1.57075" velocity="15"/>
    <dynamics damping="0.1" friction="0.0"/>
    <origin rpy="0 0 0" xyz="-0.01 0 0.1"/>
    <parent link="neck_pitch_link"/>
    <child link="head_depth_cam_mount_link"/>
  </joint>
  <link name="camera_link">
    <inertial>
      <mass value="0.05"/>
      <inertia ixx="4.16666667e-06" ixy="0.0" ixz="0.0" iyy="6.6666666667e-6" iyz="0.0" izz="04.16666667e-06"/>
    </inertial>
    <visual>
      <geometry>
        <box size="0.01 0.01 0.01"/>
      </geometry>
      <origin rpy="0 0 0" xyz="0 0 0"/>
      <material name="white"/>
    </visual>
    <collision>
      <geometry>
        <box size="0.01 0.01 0.01"/>
      </geometry>
      <origin rpy="0 0 0" xyz="0 0 0"/>
    </collision>
  </link>
  <joint name="head_depth_cam_mount2camera_joint" type="fixed">
    <origin rpy="0 0 0" xyz="0.05 0 0.03"/>
    <parent link="head_depth_cam_mount_link"/>
    <child link="camera_link"/>
  </joint>
  <link name="right_ear_link">
    <inertial>
      <mass value="0.05"/>
      <inertia ixx="4.16666667e-06" ixy="0.0" ixz="0.0" iyy="6.6666666667e-6" iyz="0.0" izz="04.16666667e-06"/>
    </inertial>
    <visual>
      <geometry>
        <mesh filename="package://rx1_description/meshes/head/right_ear_link.stl"/>
      </geometry>
      <origin rpy="0 0 0" xyz="0 0 0"/>
      <material name="white"/>
    </visual>
    <collision>
      <geometry>
        <mesh filename="package://rx1_description/meshes/head/right_ear_link.stl"/>
      </geometry>
      <origin rpy="0 0 0" xyz="0 0 0"/>
    </collision>
  </link>
  <joint name="head_depth_cam_mount2right_ear_joint" type="revolute">
    <axis xyz="0 1 0"/>
    <limit effort="50.0" lower="-1.57075" upper="1.57075" velocity="15"/>
    <dynamics damping="0.1" friction="0.0"/>
    <origin rpy="0 0 0" xyz="0 -0.065 0.045"/>
    <parent link="head_depth_cam_mount_link"/>
    <child link="right_ear_link"/>
  </joint>
  <link name="left_ear_link">
    <inertial>
      <mass value="0.05"/>
      <inertia ixx="4.16666667e-06" ixy="0.0" ixz="0.0" iyy="6.6666666667e-6" iyz="0.0" izz="04.16666667e-06"/>
    </inertial>
    <visual>
      <geometry>
        <mesh filename="package://rx1_description/meshes/head/left_ear_link.stl"/>
      </geometry>
      <origin rpy="0 0 0" xyz="0 0 0"/>
      <material name="white"/>
    </visual>
    <collision>
      <geometry>
        <mesh filename="package://rx1_description/meshes/head/left_ear_link.stl"/>
      </geometry>
      <origin rpy="0 0 0" xyz="0 0 0"/>
    </collision>
  </link>
  <joint name="head_depth_cam_mount2left_ear_joint" type="revolute">
    <axis xyz="0 1 0"/>
    <limit effort="50.0" lower="-1.57075" upper="1.57075" velocity="15"/>
    <dynamics damping="0.1" friction="0.0"/>
    <origin rpy="0 0 0" xyz="0 0.065 0.045"/>
    <parent link="head_depth_cam_mount_link"/>
    <child link="left_ear_link"/>
  </joint>
  <!--                            HEAD END                           -->
  <link name="right_shoul_base_link">
    <inertial>
      <mass value="0.2"/>
      <inertia ixx="4.16666667e-06" ixy="0.0" ixz="0.0" iyy="6.6666666667e-6" iyz="0.0" izz="04.16666667e-06"/>
    </inertial>
    <visual>
      <geometry>
        <cylinder length="0.075" radius="0.02"/>
      </geometry>
      <origin rpy="0 0 0" xyz="0 0 0.0375"/>
      <material name="white"/>
    </visual>
    <collision>
      <geometry>
        <cylinder length="0.075" radius="0.02"/>
      </geometry>
      <origin rpy="0 0 0" xyz="0 0 0.0375"/>
    </collision>
  </link>
  <joint name="head_base2right_shoul_base_joint" type="fixed">
    <origin rpy="1.04706195 0 0" xyz="0 -0.12 -0.05"/>
    <parent link="head_base_link"/>
    <child link="right_shoul_base_link"/>
  </joint>
  <link name="right_shoul_link">
    <inertial>
      <mass value="0.2"/>
      <inertia ixx="1.0" ixy="0.0" ixz="0.0" iyy="1.0" iyz="0.0" izz="1.0"/>
    </inertial>
    <visual>
      <geometry>
        <cylinder length="0.08" radius="0.03"/>
      </geometry>
      <origin rpy="0 0 0" xyz="0 0 0.04"/>
      <material name="red"/>
    </visual>
    <collision>
      <geometry>
        <cylinder length="0.08" radius="0.03"/>
      </geometry>
      <origin rpy="0 0 0" xyz="0 0 0.04"/>
    </collision>
  </link>
  <joint name="right_shoul_base2shoul_joint" type="revolute">
    <axis xyz="0 0 1"/>
    <limit effort="50.0" lower="-2.5132000000000003" upper="2.5132000000000003" velocity="15"/>
    <dynamics damping="0.5" friction="0.1"/>
    <origin rpy="0 0 0" xyz="0 0 0.075"/>
    <parent link="right_shoul_base_link"/>
    <child link="right_shoul_link"/>
  </joint>
  <link name="right_shoul_rot_link">
    <inertial>
      <mass value="0.2"/>
      <inertia ixx="1.0" ixy="0.0" ixz="0.0" iyy="1.0" iyz="0.0" izz="1.0"/>
    </inertial>
    <visual>
      <geometry>
        <cylinder length="0.04" radius="0.03"/>
      </geometry>
      <origin rpy="0 1.57075 0" xyz="0 0 0"/>
      <material name="blue"/>
    </visual>
    <collision>
      <geometry>
        <cylinder length="0.04" radius="0.03"/>
      </geometry>
      <origin rpy="0 1.57075 0" xyz="0 0 0"/>
    </collision>
  </link>
  <joint name="right_shoul2shoul_rot_joint" type="revolute">
    <axis xyz="1 0 0"/>
    <limit effort="50.0" lower="-1.57075" upper="0.5026400000000001" velocity="15"/>
    <dynamics damping="0.5" friction="0.1"/>
    <origin rpy="-1.04706195 0 0" xyz="0 0 0.08"/>
    <parent link="right_shoul_link"/>
    <child link="right_shoul_rot_link"/>
  </joint>
  <link name="right_upper_arm_link">
    <inertial>
      <mass value="0.1"/>
      <inertia ixx="1.0" ixy="0.0" ixz="0.0" iyy="1.0" iyz="0.0" izz="1.0"/>
    </inertial>
    <visual>
      <geometry>
        <!--cylinder length="0.085" radius="0.015" /-->
        <mesh filename="package://rx1_description/meshes/right_arm/right_upper_arm_link.stl"/>
      </geometry>
      <origin rpy="0 0 0" xyz="0 0 0"/>
      <material name="white"/>
    </visual>
    <collision>
      <geometry>
        <!--cylinder length="0.085" radius="0.015" /-->
        <mesh filename="package://rx1_description/meshes/right_arm/right_upper_arm_link.stl"/>
      </geometry>
      <origin rpy="0 0 0" xyz="0 0 0"/>
    </collision>
  </link>
  <joint name="right_shoul_rot2upper_arm_joint" type="fixed">
    <origin rpy="0 0 0" xyz="0 0 -0.0625"/>
    <parent link="right_shoul_rot_link"/>
    <child link="right_upper_arm_link"/>
  </joint>
  <link name="right_armrot_link">
    <inertial>
      <mass value="0.1"/>
      <inertia ixx="1.0" ixy="0.0" ixz="0.0" iyy="1.0" iyz="0.0" izz="1.0"/>
    </inertial>
    <visual>
      <geometry>
        <!--cylinder length="0.22" radius="0.03" /-->
        <mesh filename="package://rx1_description/meshes/right_arm/right_elbow_link.stl"/>
      </geometry>
      <origin rpy="0 0 0" xyz="0 0 -0.11"/>
      <material name="white"/>
    </visual>
    <collision>
      <geometry>
        <cylinder length="0.22" radius="0.03"/>
      </geometry>
      <origin rpy="0 0 0" xyz="0 0 -0.11"/>
    </collision>
  </link>
  <joint name="right_arm2armrot_joint" type="revolute">
    <axis xyz="0 0 1"/>
    <limit effort="50.0" lower="-1.57075" upper="1.57075" velocity="15"/>
    <dynamics damping="0.1" friction="0.1"/>
    <origin rpy="0 0 0" xyz="0 0 -0.0625"/>
    <parent link="right_upper_arm_link"/>
    <child link="right_armrot_link"/>
  </joint>
  <link name="right_elbow_link">
    <inertial>
      <mass value="0.1"/>
      <inertia ixx="1.0" ixy="0.0" ixz="0.0" iyy="1.0" iyz="0.0" izz="1.0"/>
    </inertial>
    <visual>
      <geometry>
        <cylinder length="0.08" radius="0.03"/>
      </geometry>
      <origin rpy="0 1.57075 -1.57075" xyz="0 0 0"/>
      <material name="blue"/>
    </visual>
    <collision>
      <geometry>
        <cylinder length="0.08" radius="0.03"/>
      </geometry>
      <origin rpy="0 1.57075 -1.57075" xyz="0 0 0"/>
    </collision>
  </link>
  <joint name="right_armrot2elbow_joint" type="revolute">
    <axis xyz="0 1 0"/>
    <limit effort="50.0" lower="-2.19905" upper="0" velocity="15"/>
    <dynamics damping="0.1" friction="0.1"/>
    <origin rpy="0 0 0" xyz="0 0 -0.22"/>
    <parent link="right_armrot_link"/>
    <child link="right_elbow_link"/>
  </joint>
  <link name="right_forearm_link">
    <inertial>
      <mass value="0.1"/>
      <inertia ixx="1.0" ixy="0.0" ixz="0.0" iyy="1.0" iyz="0.0" izz="1.0"/>
    </inertial>
    <visual>
      <geometry>
        <cylinder length="0.09" radius="0.03"/>
      </geometry>
      <origin rpy="0 0 0" xyz="0 0 0"/>
      <material name="white"/>
    </visual>
    <collision>
      <geometry>
        <cylinder length="0.09" radius="0.03"/>
      </geometry>
      <origin rpy="0 0 0" xyz="0 0 0"/>
    </collision>
  </link>
  <joint name="right_elbow2forearm_joint" type="fixed">
    <origin rpy="0 0 0" xyz="0 0 -0.045"/>
    <parent link="right_elbow_link"/>
    <child link="right_forearm_link"/>
  </joint>
  <link name="right_forearmrot_link">
    <inertial>
      <mass value="0.1"/>
      <inertia ixx="1.0" ixy="0.0" ixz="0.0" iyy="1.0" iyz="0.0" izz="1.0"/>
    </inertial>
    <visual>
      <geometry>
        <!--cylinder length="0.18" radius="0.015" /-->
        <mesh filename="package://rx1_description/meshes/right_arm/right_forearm_link.stl"/>
      </geometry>
      <origin rpy="0 0 0" xyz="0 0 -0.09"/>
      <material name="white"/>
    </visual>
    <collision>
      <geometry>
        <cylinder length="0.18" radius="0.015"/>
      </geometry>
      <origin rpy="0 0 0" xyz="0 0 -0.09"/>
    </collision>
  </link>
  <joint name="right_forearm2forearmrot_joint" type="revolute">
    <axis xyz="0 0 1"/>
    <limit effort="50.0" lower="-1.57075" upper="1.57075" velocity="15"/>
    <dynamics damping="0.1" friction="0.1"/>
    <origin rpy="0 0 0" xyz="0 0 -0.045"/>
    <parent link="right_forearm_link"/>
    <child link="right_forearmrot_link"/>
  </joint>
  <link name="right_forearm_pitch_link">
    <inertial>
      <mass value="0.1"/>
      <inertia ixx="1.0" ixy="0.0" ixz="0.0" iyy="1.0" iyz="0.0" izz="1.0"/>
    </inertial>
    <visual>
      <geometry>
        <cylinder length="0.03" radius="0.015"/>
      </geometry>
      <origin rpy="1.57075 0 0" xyz="0 0 0"/>
      <material name="blue"/>
    </visual>
    <collision>
      <geometry>
        <cylinder length="0.03" radius="0.01"/>
      </geometry>
      <origin rpy="1.57075 0 0" xyz="0 0 0"/>
    </collision>
  </link>
  <joint name="right_forearmrot2forearm_pitch_joint" type="revolute">
    <axis xyz="0 1 0"/>
    <limit effort="50.0" lower="-0.785375" upper="0.785375" velocity="15"/>
    <dynamics damping="0.1" friction="0.1"/>
    <origin rpy="0 0 0" xyz="0 0 -0.18"/>
    <parent link="right_forearmrot_link"/>
    <child link="right_forearm_pitch_link"/>
  </joint>
  <link name="right_forearm_roll_link">
    <inertial>
      <mass value="0.1"/>
      <inertia ixx="1.0" ixy="0.0" ixz="0.0" iyy="1.0" iyz="0.0" izz="1.0"/>
    </inertial>
    <visual>
      <geometry>
        <cylinder length="0.03" radius="0.015"/>
      </geometry>
      <origin rpy="0 1.57075 0" xyz="0 0 0"/>
      <material name="red"/>
    </visual>
    <collision>
      <geometry>
        <cylinder length="0.03" radius="0.01"/>
      </geometry>
      <origin rpy="0 1.57075 0" xyz="0 0 0"/>
    </collision>
  </link>
  <joint name="right_forearm_pitch2forearm_roll_joint" type="revolute">
    <axis xyz="1 0 0"/>
    <limit effort="50.0" lower="-0.785375" upper="0.785375" velocity="15"/>
    <dynamics damping="0.1" friction="0.1"/>
    <origin rpy="0 0 0" xyz="0 0 0"/>
    <parent link="right_forearm_pitch_link"/>
    <child link="right_forearm_roll_link"/>
  </joint>
  <!-- Palm -->
  <link name="right_palm_lower">
    <visual>
      <origin rpy="0 -0 0" xyz="-0.020095249652862544332 0.025757756134899473244 -0.034722403578460216134"/>
      <geometry>
        <mesh filename="package://rx1_description/meshes/leap_hand/right_palm_lower.stl"/>
      </geometry>
      <material name="right_palm_lower_material">
        <color rgba="0.60392156862745094426 0.14901960784313725283 0.14901960784313725283 1.0"/>
      </material>
    </visual>
    <collision>
      <origin rpy="0 -0 0" xyz="-0.020095249652862544332 0.025757756134899473244 -0.034722403578460216134"/>
      <geometry>
        <mesh filename="package://rx1_description/meshes/leap_hand/right_palm_lower.stl"/>
      </geometry>
    </collision>
    <inertial>
      <origin rpy="0 0 0" xyz="0 0 0"/>
      <mass value="0.237"/>
      <inertia ixx="0.000354094" ixy="-0.000001193" ixz="-0.000002445" iyy="0.000260915" iyz="-0.000002905" izz="0.000529257"/>
    </inertial>
  </link>
  <!-- Index finger chain -->
  <link name="right_index_mcp_link">
    <visual>
      <origin rpy="1.6375789613220999807e-15 -1.0210473302491019535e-30 1.7177968783327987474e-31" xyz="0.0084069022611744960438 0.0077662438597169954416 0.014657354985032912051"/>
      <geometry>
        <mesh filename="package://rx1_description/meshes/leap_hand/right_mcp_joint.stl"/>
      </geometry>
      <material name="right_index_mcp_material">
        <color rgba="0.86666666666666669627 0.86666666666666669627 0.050980392156862744391 1.0"/>
      </material>
    </visual>
    <collision>
      <origin rpy="1.6375789613220999807e-15 -1.0210473302491019535e-30 1.7177968783327987474e-31" xyz="0.0084069022611744960438 0.0077662438597169954416 0.014657354985032912051"/>
      <geometry>
        <mesh filename="package://rx1_description/meshes/leap_hand/right_mcp_joint.stl"/>
      </geometry>
    </collision>
    <inertial>
      <origin rpy="0 0 0" xyz="0 0 0"/>
      <mass value="0.044"/>
      <inertia ixx="0.000011499" ixy="0.000003049" ixz="0.000000121" iyy="0.000007796" iyz="0.000000112" izz="0.000014759"/>
    </inertial>
  </link>
  <link name="right_index_pip_link">
    <visual>
      <origin rpy="-1.570796326794896558 -1.570796326794896336 0" xyz="0.0096433630922713280131 0.00029999999999998951117 0.00078403401041737645627"/>
      <geometry>
        <mesh filename="package://rx1_description/meshes/leap_hand/right_pip.stl"/>
      </geometry>
      <material name="right_index_pip_material">
        <color rgba="0.74901960784313725839 0.74901960784313725839 0.74901960784313725839 1.0"/>
      </material>
    </visual>
    <collision>
      <origin rpy="-1.570796326794896558 -1.570796326794896336 0" xyz="0.0096433630922713280131 0.00029999999999998951117 0.00078403401041737645627"/>
      <geometry>
        <mesh filename="package://rx1_description/meshes/leap_hand/right_pip.stl"/>
      </geometry>
    </collision>
    <inertial>
      <origin rpy="0 0 0" xyz="0 0 0"/>
      <mass value="0.032"/>
      <inertia ixx="0.000004798" ixy="0.000000012" ixz="0.000000004" iyy="0.000002862" iyz="0.000000011" izz="0.000004234"/>
    </inertial>
  </link>
  <link name="right_index_dip_link">
    <visual>
      <origin rpy="-3.141592653589793116 4.5075111242164408299e-32 4.4395481053923607589e-32" xyz="0.021133352895225002849 -0.0084321191467048792201 0.0097850881620952408213"/>
      <geometry>
        <mesh filename="package://rx1_description/meshes/leap_hand/right_dip.stl"/>
      </geometry>
      <material name="right_index_dip_material">
        <color rgba="0.86666666666666669627 0.86666666666666669627 0.050980392156862744391 1.0"/>
      </material>
    </visual>
    <collision>
      <origin rpy="-3.141592653589793116 4.5075111242164408299e-32 4.4395481053923607589e-32" xyz="0.021133352895225002849 -0.0084321191467048792201 0.0097850881620952408213"/>
      <geometry>
        <mesh filename="package://rx1_description/meshes/leap_hand/right_dip.stl"/>
      </geometry>
    </collision>
    <inertial>
      <origin rpy="0 0 0" xyz="0 0 0"/>
      <mass value="0.037"/>
      <inertia ixx="0.000005542" ixy="-0.000000607" ixz="-0.000000017" iyy="0.000005727" iyz="-0.000000023" izz="0.000006682"/>
    </inertial>
  </link>
  <link name="right_index_fingertip">
    <visual>
      <origin rpy="3.141592653589793116 1.1993117970061734707e-33 4.4395481053923607589e-32" xyz="0.013286424108533503169 -0.0061142383865419869249 0.014499999999999497666"/>
      <geometry>
        <mesh filename="package://rx1_description/meshes/leap_hand/right_fingertip.stl"/>
      </geometry>
      <material name="right_index_fingertip_material">
        <color rgba="0.86666666666666669627 0.86666666666666669627 0.050980392156862744391 1.0"/>
      </material>
    </visual>
    <collision>
      <origin rpy="3.141592653589793116 1.1993117970061734707e-33 4.4395481053923607589e-32" xyz="0.013286424108533503169 -0.0061142383865419869249 0.014499999999999497666"/>
      <geometry>
        <mesh filename="package://rx1_description/meshes/leap_hand/right_fingertip.stl"/>
      </geometry>
    </collision>
    <inertial>
      <origin rpy="0 0 0" xyz="0 0 0"/>
      <mass value="0.016"/>
      <inertia ixx="0.000003368" ixy="0.000000115" ixz="0" iyy="0.000001556" iyz="0" izz="0.000002863"/>
    </inertial>
  </link>
  <!-- Index finger joints -->
  <joint name="right_index_joint_mcp_to_pip" type="revolute">
    <origin rpy="-1.570796326794896558 -1.0065212660796336576e-15 1.5707963267948943376" xyz="-0.012200000000000007713 0.038099999999999994982 0.014500000000000000736"/>
    <parent link="right_index_mcp_link"/>
    <child link="right_index_pip_link"/>
    <axis xyz="0 0 -1"/>
    <limit effort="0.95" lower="-1.047" upper="1.047" velocity="8.48"/>
  </joint>
  <joint name="right_index_joint_palm_to_mcp" type="revolute">
    <origin rpy="1.5707963267948950037 1.5707963267948945596 0" xyz="-0.0070952496528625457958 0.023057756134899472233 -0.01872240357846021927"/>
    <parent link="right_palm_lower"/>
    <child link="right_index_mcp_link"/>
    <axis xyz="0 0 -1"/>
    <limit effort="0.95" lower="-0.314" upper="2.23" velocity="8.48"/>
  </joint>
  <joint name="right_index_joint_pip_to_dip" type="revolute">
    <origin rpy="1.5707963267948958919 -1.570796326794896336 0" xyz="0.01499999999999996822 0.014299999999999904801 -0.012999999999999824196"/>
    <parent link="right_index_pip_link"/>
    <child link="right_index_dip_link"/>
    <axis xyz="0 0 -1"/>
    <limit effort="0.95" lower="-0.506" upper="1.885" velocity="8.48"/>
  </joint>
  <joint name="right_index_joint_dip_to_fingertip" type="revolute">
    <origin rpy="4.5935029425113685044e-17 -2.8730071914463794583e-16 4.4395481053923607589e-32" xyz="-4.0880582495572692636e-09 -0.036100004210367367397 0.00020000000000007858714"/>
    <parent link="right_index_dip_link"/>
    <child link="right_index_fingertip"/>
    <axis xyz="0 0 -1"/>
    <limit effort="0.95" lower="-0.366" upper="2.042" velocity="8.48"/>
  </joint>
  <!-- Middle finger chain -->
  <link name="right_middle_mcp_link">
    <visual>
      <origin rpy="1.6375789613220999807e-15 -1.0076465469034000467e-30 2.1209300131419907151e-61" xyz="0.0084069022611744960438 0.0077662438597169954416 0.014657354985032913786"/>
      <geometry>
        <mesh filename="package://rx1_description/meshes/leap_hand/right_mcp_joint.stl"/>
      </geometry>
      <material name="right_middle_mcp_material">
        <color rgba="0.86666666666666669627 0.86666666666666669627 0.050980392156862744391 1.0"/>
      </material>
    </visual>
    <collision>
      <origin rpy="1.6375789613220999807e-15 -1.0076465469034000467e-30 2.1209300131419907151e-61" xyz="0.0084069022611744960438 0.0077662438597169954416 0.014657354985032913786"/>
      <geometry>
        <mesh filename="package://rx1_description/meshes/leap_hand/right_mcp_joint.stl"/>
      </geometry>
    </collision>
    <inertial>
      <origin rpy="0 0 0" xyz="0 0 0"/>
      <mass value="0.044"/>
      <inertia ixx="0.000011499" ixy="0.000003049" ixz="0.000000121" iyy="0.000007796" iyz="0.000000112" izz="0.000014759"/>
    </inertial>
  </link>
  <link name="right_middle_pip_link">
    <visual>
      <origin rpy="-1.570796326794896558 -1.570796326794896336 0" xyz="0.0096433630922713280131 0.00029999999999999471534 0.00078403401041737645627"/>
      <geometry>
        <mesh filename="package://rx1_description/meshes/leap_hand/right_pip.stl"/>
      </geometry>
      <material name="right_middle_pip_material">
        <color rgba="0.74901960784313725839 0.74901960784313725839 0.74901960784313725839 1.0"/>
      </material>
    </visual>
    <collision>
      <origin rpy="-1.570796326794896558 -1.570796326794896336 0" xyz="0.0096433630922713280131 0.00029999999999999471534 0.00078403401041737645627"/>
      <geometry>
        <mesh filename="package://rx1_description/meshes/leap_hand/right_pip.stl"/>
      </geometry>
    </collision>
    <inertial>
      <origin rpy="0 0 0" xyz="0 0 0"/>
      <mass value="0.032"/>
      <inertia ixx="0.000004798" ixy="0.000000012" ixz="0.000000004" iyy="0.000002862" iyz="0.000000011" izz="0.000004234"/>
    </inertial>
  </link>
  <link name="right_middle_dip_link">
    <visual>
      <origin rpy="-3.141592653589793116 2.1146933785271955805e-32 1.4408183216511868558e-31" xyz="0.021133352895225002849 -0.0084321191467048653423 0.0097850881620952373519"/>
      <geometry>
        <mesh filename="package://rx1_description/meshes/leap_hand/right_dip.stl"/>
      </geometry>
      <material name="right_middle_dip_material">
        <color rgba="0.86666666666666669627 0.86666666666666669627 0.050980392156862744391 1.0"/>
      </material>
    </visual>
    <collision>
      <origin rpy="-3.141592653589793116 2.1146933785271955805e-32 1.4408183216511868558e-31" xyz="0.021133352895225002849 -0.0084321191467048653423 0.0097850881620952373519"/>
      <geometry>
        <mesh filename="package://rx1_description/meshes/leap_hand/right_dip.stl"/>
      </geometry>
    </collision>
    <inertial>
      <origin rpy="0 0 0" xyz="0 0 0"/>
      <mass value="0.037"/>
      <inertia ixx="0.000005542" ixy="-0.000000607" ixz="-0.000000017" iyy="0.000005727" iyz="-0.000000023" izz="0.000006682"/>
    </inertial>
  </link>
  <link name="right_middle_fingertip">
    <visual>
      <origin rpy="3.141592653589793116 -4.3179597882835943107e-33 1.4408183216511868558e-31" xyz="0.01328642410853349623 -0.0061142383865420008027 0.014499999999999495931"/>
      <geometry>
        <mesh filename="package://rx1_description/meshes/leap_hand/right_fingertip.stl"/>
      </geometry>
      <material name="right_middle_fingertip_material">
        <color rgba="0.86666666666666669627 0.86666666666666669627 0.050980392156862744391 1.0"/>
      </material>
    </visual>
    <collision>
      <origin rpy="3.141592653589793116 -4.3179597882835943107e-33 1.4408183216511868558e-31" xyz="0.01328642410853349623 -0.0061142383865420008027 0.014499999999999495931"/>
      <geometry>
        <mesh filename="package://rx1_description/meshes/leap_hand/right_fingertip.stl"/>
      </geometry>
    </collision>
    <inertial>
      <origin rpy="0 0 0" xyz="0 0 0"/>
      <mass value="0.016"/>
      <inertia ixx="0.000003368" ixy="0.000000115" ixz="0" iyy="0.000001556" iyz="0" izz="0.000002863"/>
    </inertial>
  </link>
  <!-- Middle finger joints -->
  <joint name="right_middle_joint_mcp_to_pip" type="revolute">
    <origin rpy="-1.570796326794896558 -1.0065212760057939085e-15 1.5707963267948943376" xyz="-0.012200000000000019856 0.038099999999999981104 0.01450000000000000594"/>
    <parent link="right_middle_mcp_link"/>
    <child link="right_middle_pip_link"/>
    <axis xyz="0 0 -1"/>
    <limit effort="0.95" lower="-1.047" upper="1.047" velocity="8.48"/>
  </joint>
  <joint name="right_middle_joint_palm_to_mcp" type="revolute">
    <origin rpy="1.570796326794896558 1.570796326794896558 0" xyz="-0.0070952496528625388569 -0.022392243865100525113 -0.018722403578460229678"/>
    <parent link="right_palm_lower"/>
    <child link="right_middle_mcp_link"/>
    <axis xyz="0 0 -1"/>
    <limit effort="0.95" lower="-0.314" upper="2.23" velocity="8.48"/>
  </joint>
  <joint name="right_middle_joint_pip_to_dip" type="revolute">
    <origin rpy="1.5707963267948958919 -1.570796326794896336 0" xyz="0.014999999999999975159 0.014300000000000000211 -0.013000000000000018485"/>
    <parent link="right_middle_pip_link"/>
    <child link="right_middle_dip_link"/>
    <axis xyz="0 0 -1"/>
    <limit effort="0.95" lower="-0.506" upper="1.885" velocity="8.48"/>
  </joint>
  <joint name="right_middle_joint_dip_to_fingertip" type="revolute">
    <origin rpy="4.5935029425113654229e-17 -2.8730071914463794583e-16 1.4408183216511868558e-31" xyz="1.0061396160665481148e-16 -0.036099999999999854428 0.00020000000000007858714"/>
    <parent link="right_middle_dip_link"/>
    <child link="right_middle_fingertip"/>
    <axis xyz="0 0 -1"/>
    <limit effort="0.95" lower="-0.366" upper="2.042" velocity="8.48"/>
  </joint>
  <!-- Ring finger chain -->
  <link name="right_ring_mcp_link">
    <visual>
      <origin rpy="1.6375789613220999807e-15 -1.0059504988632626953e-30 5.729641584552035421e-32" xyz="0.0084069022611744995133 0.0077662438597169963089 0.014657354985032913786"/>
      <geometry>
        <mesh filename="package://rx1_description/meshes/leap_hand/right_mcp_joint.stl"/>
      </geometry>
      <material name="right_ring_mcp_material">
        <color rgba="0.86666666666666669627 0.86666666666666669627 0.050980392156862744391 1.0"/>
      </material>
    </visual>
    <collision>
      <origin rpy="1.6375789613220999807e-15 -1.0059504988632626953e-30 5.729641584552035421e-32" xyz="0.0084069022611744995133 0.0077662438597169963089 0.014657354985032913786"/>
      <geometry>
        <mesh filename="package://rx1_description/meshes/leap_hand/right_mcp_joint.stl"/>
      </geometry>
    </collision>
    <inertial>
      <origin rpy="0 0 0" xyz="0 0 0"/>
      <mass value="0.044"/>
      <inertia ixx="0.000011499" ixy="0.000003049" ixz="0.000000121" iyy="0.000007796" iyz="0.000000112" izz="0.000014759"/>
    </inertial>
  </link>
  <link name="right_ring_pip_link">
    <visual>
      <origin rpy="-1.570796326794896558 -1.570796326794896336 0" xyz="0.0096433630922713314826 0.00029999999999998083755 0.00078403401041737645627"/>
      <geometry>
        <mesh filename="package://rx1_description/meshes/leap_hand/right_pip.stl"/>
      </geometry>
      <material name="right_ring_pip_material">
        <color rgba="0.74901960784313725839 0.74901960784313725839 0.74901960784313725839 1.0"/>
      </material>
    </visual>
    <collision>
      <origin rpy="-1.570796326794896558 -1.570796326794896336 0" xyz="0.0096433630922713314826 0.00029999999999998083755 0.00078403401041737645627"/>
      <geometry>
        <mesh filename="package://rx1_description/meshes/leap_hand/right_pip.stl"/>
      </geometry>
    </collision>
    <inertial>
      <origin rpy="0 0 0" xyz="0 0 0"/>
      <mass value="0.032"/>
      <inertia ixx="0.000004798" ixy="0.000000012" ixz="0.000000004" iyy="0.000002862" iyz="0.000000011" izz="0.000004234"/>
    </inertial>
  </link>
  <link name="right_ring_dip_link">
    <visual>
      <origin rpy="-3.141592653589793116 -1.4095651113919093005e-33 1.5565411607615035382e-32" xyz="0.021133352895225006318 -0.0084321191467048653423 0.0097850881620952373519"/>
      <geometry>
        <mesh filename="package://rx1_description/meshes/leap_hand/right_dip.stl"/>
      </geometry>
      <material name="right_ring_dip_material">
        <color rgba="0.86666666666666669627 0.86666666666666669627 0.050980392156862744391 1.0"/>
      </material>
    </visual>
    <collision>
      <origin rpy="-3.141592653589793116 -1.4095651113919093005e-33 1.5565411607615035382e-32" xyz="0.021133352895225006318 -0.0084321191467048653423 0.0097850881620952373519"/>
      <geometry>
        <mesh filename="package://rx1_description/meshes/leap_hand/right_dip.stl"/>
      </geometry>
    </collision>
    <inertial>
      <origin rpy="0 0 0" xyz="0 0 0"/>
      <mass value="0.037"/>
      <inertia ixx="0.000005542" ixy="-0.000000607" ixz="-0.000000017" iyy="0.000005727" iyz="-0.000000023" izz="0.000006682"/>
    </inertial>
  </link>
  <link name="right_ring_fingertip">
    <visual>
      <origin rpy="3.141592653589793116 8.6170716950575402125e-33 1.5565411607615035382e-32" xyz="0.013286424108533501434 -0.0061142383865419869249 0.0144999999999994994"/>
      <geometry>
        <mesh filename="package://rx1_description/meshes/leap_hand/right_fingertip.stl"/>
      </geometry>
      <material name="right_ring_fingertip_material">
        <color rgba="0.86666666666666669627 0.86666666666666669627 0.050980392156862744391 1.0"/>
      </material>
    </visual>
    <collision>
      <origin rpy="3.141592653589793116 8.6170716950575402125e-33 1.5565411607615035382e-32" xyz="0.013286424108533501434 -0.0061142383865419869249 0.0144999999999994994"/>
      <geometry>
        <mesh filename="package://rx1_description/meshes/leap_hand/right_fingertip.stl"/>
      </geometry>
    </collision>
    <inertial>
      <origin rpy="0 0 0" xyz="0 0 0"/>
      <mass value="0.016"/>
      <inertia ixx="0.000003368" ixy="0.000000115" ixz="0" iyy="0.000001556" iyz="0" izz="0.000002863"/>
    </inertial>
  </link>
  <!-- Ring finger joints -->
  <joint name="right_ring_joint_mcp_to_pip" type="revolute">
    <origin rpy="-1.570796326794896558 -1.0065212660796360242e-15 1.5707963267948943376" xyz="-0.012200000000000004244 0.038100000000000001921 0.014499999999999999001"/>
    <parent link="right_ring_mcp_link"/>
    <child link="right_ring_pip_link"/>
    <axis xyz="0 0 -1"/>
    <limit effort="0.95" lower="-1.047" upper="1.047" velocity="8.48"/>
  </joint>
  <joint name="right_ring_joint_palm_to_mcp" type="revolute">
    <origin rpy="1.5707963267948950037 1.5707963267948945596 0" xyz="-0.0070952454426398371343 -0.067842243865100515521 -0.018722407666402932774"/>
    <parent link="right_palm_lower"/>
    <child link="right_ring_mcp_link"/>
    <axis xyz="0 0 -1"/>
    <limit effort="0.95" lower="-0.314" upper="2.23" velocity="8.48"/>
  </joint>
  <joint name="right_ring_joint_pip_to_dip" type="revolute">
    <origin rpy="1.5707963267948958919 -1.570796326794896336 0" xyz="0.014999999999999971689 0.014299999999999951639 -0.012999999999999959505"/>
    <parent link="right_ring_pip_link"/>
    <child link="right_ring_dip_link"/>
    <axis xyz="0 0 -1"/>
    <limit effort="0.95" lower="-0.506" upper="1.885" velocity="8.48"/>
  </joint>
  <joint name="right_ring_joint_dip_to_fingertip" type="revolute">
    <origin rpy="4.5935029425113685044e-17 -2.8730071914463799514e-16 1.5565411607615035382e-32" xyz="9.7144514654701197287e-17 -0.036099999999999868305 0.00020000000000007511769"/>
    <parent link="right_ring_dip_link"/>
    <child link="right_ring_fingertip"/>
    <axis xyz="0 0 -1"/>
    <limit effort="0.95" lower="-0.366" upper="2.042" velocity="8.48"/>
  </joint>
  <!-- Thumb chain -->
  <link name="right_thumb_base">
    <visual>
      <origin rpy="-1.570796326794896558 -1.570796326794896336 0" xyz="-0.0053566369077286714317 0.00029999999999999991951 0.00078403401041737819099"/>
      <geometry>
        <mesh filename="package://rx1_description/meshes/leap_hand/right_pip.stl"/>
      </geometry>
      <material name="right_thumb_base_material">
        <color rgba="0.74901960784313725839 0.74901960784313725839 0.74901960784313725839 1.0"/>
      </material>
    </visual>
    <collision>
      <origin rpy="-1.570796326794896558 -1.570796326794896336 0" xyz="-0.0053566369077286714317 0.00029999999999999991951 0.00078403401041737819099"/>
      <geometry>
        <mesh filename="package://rx1_description/meshes/leap_hand/right_pip.stl"/>
      </geometry>
    </collision>
    <inertial>
      <origin rpy="0 0 0" xyz="0 0 0"/>
      <mass value="0.032"/>
      <inertia ixx="0.000004798" ixy="0.000000012" ixz="0.000000004" iyy="0.000002862" iyz="0.000000011" izz="0.000004234"/>
    </inertial>
  </link>
  <link name="right_thumb_pip_link">
    <visual>
      <origin rpy="1.570796326794896558 1.6050198443300152637e-46 -3.9204996250525192755e-59" xyz="0.011961920770611186859 -5.3082538364890297089e-16 -0.015852648956664199681"/>
      <geometry>
        <mesh filename="package://rx1_description/meshes/leap_hand/right_thumb_pip.stl"/>
      </geometry>
      <material name="right_thumb_pip_material">
        <color rgba="0.86666666666666669627 0.86666666666666669627 0.050980392156862744391 1.0"/>
      </material>
    </visual>
    <collision>
      <origin rpy="1.570796326794896558 1.6050198443300152637e-46 -3.9204996250525192755e-59" xyz="0.011961920770611186859 -5.3082538364890297089e-16 -0.015852648956664199681"/>
      <geometry>
        <mesh filename="package://rx1_description/meshes/leap_hand/right_thumb_pip.stl"/>
      </geometry>
    </collision>
    <inertial>
      <origin rpy="0 0 0" xyz="0 0 0"/>
      <mass value="0.003"/>
      <inertia ixx="0.000000593" ixy="0" ixz="0" iyy="0.000000549" iyz="0" izz="0.000000224"/>
    </inertial>
  </link>
  <link name="right_thumb_dip_link">
    <visual>
      <origin rpy="1.9428902930940098942e-16 3.2751579226442200773e-15 1.1123758529657360012e-46" xyz="0.043968715707239175439 0.057952952973709198625 -0.0086286764493694757122"/>
      <geometry>
        <mesh filename="package://rx1_description/meshes/leap_hand/right_thumb_dip.stl"/>
      </geometry>
      <material name="right_thumb_dip_material">
        <color rgba="0.86666666666666669627 0.86666666666666669627 0.050980392156862744391 1.0"/>
      </material>
    </visual>
    <collision>
      <origin rpy="1.9428902930940098942e-16 3.2751579226442200773e-15 1.1123758529657360012e-46" xyz="0.043968715707239175439 0.057952952973709198625 -0.0086286764493694757122"/>
      <geometry>
        <mesh filename="package://rx1_description/meshes/leap_hand/right_thumb_dip.stl"/>
      </geometry>
    </collision>
    <inertial>
      <origin rpy="0 0 0" xyz="0 0 0"/>
      <mass value="0.038"/>
      <inertia ixx="0.000008474" ixy="0.000000241" ixz="0.000000026" iyy="0.000003841" iyz="0.000000025" izz="0.000007679"/>
    </inertial>
  </link>
  <link name="right_thumb_fingertip">
    <visual>
      <origin rpy="4.3790577010156367543e-47 -3.3306690738754701143e-16 1.2042408677791935383e-46" xyz="0.062559538462667388381 0.078459682911396988469 0.048992911807332215068"/>
      <geometry>
        <mesh filename="package://rx1_description/meshes/leap_hand/right_thumb_fingertip.stl"/>
      </geometry>
      <material name="right_thumb_fingertip_material">
        <color rgba="0.60392156862745094426 0.14901960784313725283 0.14901960784313725283 1.0"/>
      </material>
    </visual>
    <collision>
      <origin rpy="4.3790577010156367543e-47 -3.3306690738754701143e-16 1.2042408677791935383e-46" xyz="0.062559538462667388381 0.078459682911396988469 0.048992911807332215068"/>
      <geometry>
        <mesh filename="package://rx1_description/meshes/leap_hand/right_thumb_fingertip.stl"/>
      </geometry>
    </collision>
    <inertial>
      <origin rpy="0 0 0" xyz="0 0 0"/>
      <mass value="0.049"/>
      <inertia ixx="0.000020372" ixy="-0.000000489" ixz="-0.00000003" iyy="0.000004336" iyz="-0.000000097" izz="0.000019845"/>
    </inertial>
  </link>
  <!-- Thumb joints -->
  <joint name="right_thumb_joint_palm_to_base" type="revolute">
    <origin rpy="-8.2381766464939424156e-17 1.5707963267948956698 0" xyz="-0.069395249652862533996 -0.0012422438651005258004 -0.021622403578460215601"/>
    <parent link="right_palm_lower"/>
    <child link="right_thumb_base"/>
    <axis xyz="0 0 -1"/>
    <limit effort="0.95" lower="-0.349" upper="2.094" velocity="8.48"/>
  </joint>
  <joint name="right_thumb_joint_base_to_pip" type="revolute">
    <origin rpy="1.5707963267948958919 -1.570796326794896336 0" xyz="-2.7755575615628913511e-17 0.014300000000000005415 -0.013000000000000011546"/>
    <parent link="right_thumb_base"/>
    <child link="right_thumb_pip_link"/>
    <axis xyz="0 0 -1"/>
    <limit effort="0.95" lower="-0.47" upper="2.443" velocity="8.48"/>
  </joint>
  <joint name="right_thumb_joint_pip_to_dip" type="revolute">
    <origin rpy="-1.570796326794896558 1.6050198443300131245e-46 -1.9721522630516624601e-31" xyz="0 0.014499999999999966041 -0.017000000000000053263"/>
    <parent link="right_thumb_pip_link"/>
    <child link="right_thumb_dip_link"/>
    <axis xyz="0 0 -1"/>
    <limit effort="0.95" lower="-1.20" upper="1.90" velocity="8.48"/>
  </joint>
  <joint name="right_thumb_joint_dip_to_fingertip" type="revolute">
    <origin rpy="1.5063958491491781023e-44 5.4234187233935260503e-31 3.141592653589793116" xyz="-1.249000902703301108e-16 0.046599999999999863753 0.00019999999999997710581"/>
    <parent link="right_thumb_dip_link"/>
    <child link="right_thumb_fingertip"/>
    <axis xyz="0 0 -1"/>
    <limit effort="0.95" lower="-1.34" upper="1.88" velocity="8.48"/>
  </joint>
  <!-- Connect to the already defined hand -->
  <joint name="right_forearm_roll2palm_joint" type="fixed">
    <origin rpy="0 1.57075 0" xyz="0 0.04 -0.15"/>
    <parent link="right_forearm_roll_link"/>
    <child link="right_palm_lower"/>
  </joint>
  <link name="left_shoul_base_link">
    <inertial>
      <mass value="0.2"/>
      <inertia ixx="4.16666667e-06" ixy="0.0" ixz="0.0" iyy="6.6666666667e-6" iyz="0.0" izz="04.16666667e-06"/>
    </inertial>
    <visual>
      <geometry>
        <cylinder length="0.075" radius="0.02"/>
      </geometry>
      <origin rpy="0 0 0" xyz="0 0 0.0375"/>
      <material name="white"/>
    </visual>
    <collision>
      <geometry>
        <cylinder length="0.075" radius="0.02"/>
      </geometry>
      <origin rpy="0 0 0" xyz="0 0 0.0375"/>
    </collision>
  </link>
  <joint name="head_base2left_shoul_base_joint" type="fixed">
    <origin rpy="-1.04706195 0 0" xyz="0 0.12 -0.05"/>
    <parent link="head_base_link"/>
    <child link="left_shoul_base_link"/>
  </joint>
  <link name="left_shoul_link">
    <inertial>
      <mass value="0.2"/>
      <inertia ixx="1.0" ixy="0.0" ixz="0.0" iyy="1.0" iyz="0.0" izz="1.0"/>
    </inertial>
    <visual>
      <geometry>
        <cylinder length="0.08" radius="0.03"/>
      </geometry>
      <origin rpy="0 0 0" xyz="0 0 0.04"/>
      <material name="red"/>
    </visual>
    <collision>
      <geometry>
        <cylinder length="0.08" radius="0.03"/>
      </geometry>
      <origin rpy="0 0 0" xyz="0 0 0.04"/>
    </collision>
  </link>
  <joint name="left_shoul_base2shoul_joint" type="revolute">
    <axis xyz="0 0 1"/>
    <limit effort="50.0" lower="-2.5132000000000003" upper="2.5132000000000003" velocity="15"/>
    <dynamics damping="0.5" friction="0.1"/>
    <origin rpy="0 0 0" xyz="0 0 0.075"/>
    <parent link="left_shoul_base_link"/>
    <child link="left_shoul_link"/>
  </joint>
  <link name="left_shoul_rot_link">
    <inertial>
      <mass value="0.2"/>
      <inertia ixx="1.0" ixy="0.0" ixz="0.0" iyy="1.0" iyz="0.0" izz="1.0"/>
    </inertial>
    <visual>
      <geometry>
        <cylinder length="0.04" radius="0.03"/>
      </geometry>
      <origin rpy="0 1.57075 0" xyz="0 0 0"/>
      <material name="blue"/>
    </visual>
    <collision>
      <geometry>
        <cylinder length="0.04" radius="0.03"/>
      </geometry>
      <origin rpy="0 1.57075 0" xyz="0 0 0"/>
    </collision>
  </link>
  <joint name="left_shoul2shoul_rot_joint" type="revolute">
    <axis xyz="1 0 0"/>
    <limit effort="50.0" lower="-0.5026400000000001" upper="1.57075" velocity="15"/>
    <dynamics damping="0.5" friction="0.1"/>
    <origin rpy="1.04706195 0 0" xyz="0 0 0.08"/>
    <parent link="left_shoul_link"/>
    <child link="left_shoul_rot_link"/>
  </joint>
  <link name="left_upper_arm_link">
    <inertial>
      <mass value="0.1"/>
      <inertia ixx="1.0" ixy="0.0" ixz="0.0" iyy="1.0" iyz="0.0" izz="1.0"/>
    </inertial>
    <visual>
      <geometry>
        <!--cylinder length="0.085" radius="0.015" /-->
        <mesh filename="package://rx1_description/meshes/left_arm/left_upper_arm_link.stl"/>
      </geometry>
      <origin rpy="0 0 0" xyz="0 0 0"/>
      <material name="white"/>
    </visual>
    <collision>
      <geometry>
        <!--cylinder length="0.085" radius="0.015" /-->
        <mesh filename="package://rx1_description/meshes/left_arm/left_upper_arm_link.stl"/>
      </geometry>
      <origin rpy="0 0 0" xyz="0 0 0"/>
    </collision>
  </link>
  <joint name="left_shoul_rot2upper_arm_joint" type="fixed">
    <origin rpy="0 0 0" xyz="0 0 -0.0625"/>
    <parent link="left_shoul_rot_link"/>
    <child link="left_upper_arm_link"/>
  </joint>
  <link name="left_armrot_link">
    <inertial>
      <mass value="0.1"/>
      <inertia ixx="1.0" ixy="0.0" ixz="0.0" iyy="1.0" iyz="0.0" izz="1.0"/>
    </inertial>
    <visual>
      <geometry>
        <!--cylinder length="0.22" radius="0.03" /-->
        <mesh filename="package://rx1_description/meshes/left_arm/left_elbow_link.stl"/>
      </geometry>
      <origin rpy="0 0 0" xyz="0 0 -0.11"/>
      <material name="white"/>
    </visual>
    <collision>
      <geometry>
        <cylinder length="0.22" radius="0.03"/>
      </geometry>
      <origin rpy="0 0 0" xyz="0 0 -0.11"/>
    </collision>
  </link>
  <joint name="left_arm2armrot_joint" type="revolute">
    <axis xyz="0 0 1"/>
    <limit effort="50.0" lower="-1.57075" upper="1.57075" velocity="15"/>
    <dynamics damping="0.1" friction="0.1"/>
    <origin rpy="0 0 0" xyz="0 0 -0.0625"/>
    <parent link="left_upper_arm_link"/>
    <child link="left_armrot_link"/>
  </joint>
  <link name="left_elbow_link">
    <inertial>
      <mass value="0.1"/>
      <inertia ixx="1.0" ixy="0.0" ixz="0.0" iyy="1.0" iyz="0.0" izz="1.0"/>
    </inertial>
    <visual>
      <geometry>
        <cylinder length="0.08" radius="0.03"/>
      </geometry>
      <origin rpy="0 -1.57075 -1.57075" xyz="0 0 0"/>
      <material name="blue"/>
    </visual>
    <collision>
      <geometry>
        <cylinder length="0.08" radius="0.03"/>
      </geometry>
      <origin rpy="0 -1.57075 -1.57075" xyz="0 0 0"/>
    </collision>
  </link>
  <joint name="left_armrot2elbow_joint" type="revolute">
    <axis xyz="0 1 0"/>
    <limit effort="50.0" lower="-2.19905" upper="0" velocity="15"/>
    <dynamics damping="0.1" friction="0.1"/>
    <origin rpy="0 0 0" xyz="0 0 -0.22"/>
    <parent link="left_armrot_link"/>
    <child link="left_elbow_link"/>
  </joint>
  <link name="left_forearm_link">
    <inertial>
      <mass value="0.1"/>
      <inertia ixx="1.0" ixy="0.0" ixz="0.0" iyy="1.0" iyz="0.0" izz="1.0"/>
    </inertial>
    <visual>
      <geometry>
        <cylinder length="0.09" radius="0.03"/>
      </geometry>
      <origin rpy="0 0 0" xyz="0 0 0"/>
      <material name="white"/>
    </visual>
    <collision>
      <geometry>
        <cylinder length="0.09" radius="0.03"/>
      </geometry>
      <origin rpy="0 0 0" xyz="0 0 0"/>
    </collision>
  </link>
  <joint name="left_elbow2forearm_joint" type="fixed">
    <origin rpy="0 0 0" xyz="0 0 -0.045"/>
    <parent link="left_elbow_link"/>
    <child link="left_forearm_link"/>
  </joint>
  <link name="left_forearmrot_link">
    <inertial>
      <mass value="0.1"/>
      <inertia ixx="1.0" ixy="0.0" ixz="0.0" iyy="1.0" iyz="0.0" izz="1.0"/>
    </inertial>
    <visual>
      <geometry>
        <!--cylinder length="0.18" radius="0.015" /-->
        <mesh filename="package://rx1_description/meshes/left_arm/left_forearm_link.stl"/>
      </geometry>
      <origin rpy="0 0 0" xyz="0 0 -0.09"/>
      <material name="white"/>
    </visual>
    <collision>
      <geometry>
        <cylinder length="0.18" radius="0.015"/>
      </geometry>
      <origin rpy="0 0 0" xyz="0 0 -0.09"/>
    </collision>
  </link>
  <joint name="left_forearm2forearmrot_joint" type="revolute">
    <axis xyz="0 0 1"/>
    <limit effort="50.0" lower="-1.57075" upper="1.57075" velocity="15"/>
    <dynamics damping="0.1" friction="0.1"/>
    <origin rpy="0 0 0" xyz="0 0 -0.045"/>
    <parent link="left_forearm_link"/>
    <child link="left_forearmrot_link"/>
  </joint>
  <link name="left_forearm_pitch_link">
    <inertial>
      <mass value="0.1"/>
      <inertia ixx="1.0" ixy="0.0" ixz="0.0" iyy="1.0" iyz="0.0" izz="1.0"/>
    </inertial>
    <visual>
      <geometry>
        <cylinder length="0.03" radius="0.015"/>
      </geometry>
      <origin rpy="-1.57075 0 0" xyz="0 0 0"/>
      <material name="blue"/>
    </visual>
    <collision>
      <geometry>
        <cylinder length="0.03" radius="0.01"/>
      </geometry>
      <origin rpy="-1.57075 0 0" xyz="0 0 0"/>
    </collision>
  </link>
  <joint name="left_forearmrot2forearm_pitch_joint" type="revolute">
    <axis xyz="0 1 0"/>
    <limit effort="50.0" lower="-0.785375" upper="0.785375" velocity="15"/>
    <dynamics damping="0.1" friction="0.1"/>
    <origin rpy="0 0 0" xyz="0 0 -0.18"/>
    <parent link="left_forearmrot_link"/>
    <child link="left_forearm_pitch_link"/>
  </joint>
  <link name="left_forearm_roll_link">
    <inertial>
      <mass value="0.1"/>
      <inertia ixx="1.0" ixy="0.0" ixz="0.0" iyy="1.0" iyz="0.0" izz="1.0"/>
    </inertial>
    <visual>
      <geometry>
        <cylinder length="0.03" radius="0.015"/>
      </geometry>
      <origin rpy="0 -1.57075 0" xyz="0 0 0"/>
      <material name="red"/>
    </visual>
    <collision>
      <geometry>
        <cylinder length="0.03" radius="0.01"/>
      </geometry>
      <origin rpy="0 -1.57075 0" xyz="0 0 0"/>
    </collision>
  </link>
  <joint name="left_forearm_pitch2forearm_roll_joint" type="revolute">
    <axis xyz="1 0 0"/>
    <limit effort="50.0" lower="-0.785375" upper="0.785375" velocity="15"/>
    <dynamics damping="0.1" friction="0.1"/>
    <origin rpy="0 0 0" xyz="0 0 0"/>
    <parent link="left_forearm_pitch_link"/>
    <child link="left_forearm_roll_link"/>
  </joint>
  <!-- Palm -->
  <link name="left_palm_lower">
    <visual>
      <origin rpy="1.57079632679489678 1.1239611599647231752e-28 3.1415926535897908956" xyz="-0.095574224938392599027 -0.11704001150113751972 0.02077960705260517571"/>
      <geometry>
        <mesh filename="package://rx1_description/meshes/leap_hand/left_palm_lower.stl"/>
      </geometry>
      <material name="left_palm_lower_material">
        <color rgba="0.60392156862745094426 0.14901960784313725283 0.14901960784313725283 1.0"/>
      </material>
    </visual>
    <collision>
      <origin rpy="1.57079632679489678 1.1239611599647231752e-28 3.1415926535897908956" xyz="-0.095574224938392599027 -0.11704001150113751972 0.02077960705260517571"/>
      <geometry>
        <mesh filename="package://rx1_description/meshes/leap_hand/left_palm_lower.stl"/>
      </geometry>
    </collision>
    <inertial>
      <origin rpy="0 0 0" xyz="0 0 0"/>
      <mass value="0.235"/>
      <inertia ixx="0.000351007" ixy="-0.000001393" ixz="-0.000000694" iyy="0.000523205" iyz="-0.000003085" izz="0.000256996"/>
    </inertial>
  </link>
  <!-- Index finger chain -->
  <link name="left_index_mcp_link">
    <visual>
      <origin rpy="1.6375789613220999807e-15 -1.0045650589924324925e-30 -1.7121057196142940206e-44" xyz="0.008406902261174501248 0.0077662438597169980437 0.014657354985032899908"/>
      <geometry>
        <mesh filename="package://rx1_description/meshes/leap_hand/left_mcp_joint.stl"/>
      </geometry>
      <material name="left_index_mcp_material">
        <color rgba="0.86666666666666669627 0.86666666666666669627 0.050980392156862744391 1.0"/>
      </material>
    </visual>
    <collision>
      <origin rpy="1.6375789613220999807e-15 -1.0045650589924324925e-30 -1.7121057196142940206e-44" xyz="0.008406902261174501248 0.0077662438597169980437 0.014657354985032899908"/>
      <geometry>
        <mesh filename="package://rx1_description/meshes/leap_hand/left_mcp_joint.stl"/>
      </geometry>
    </collision>
    <inertial>
      <origin rpy="0 0 0" xyz="0 0 0"/>
      <mass value="0.044"/>
      <inertia ixx="0.000011499" ixy="0.000003049" ixz="0.000000121" iyy="0.000007796" iyz="0.000000112" izz="0.000014759"/>
    </inertial>
  </link>
  <link name="left_index_pip_link">
    <visual>
      <origin rpy="-1.570796326794896558 -1.570796326794896336 0" xyz="0.0096433630922713314826 0.00029999999999999471534 0.00078403401041737472155"/>
      <geometry>
        <mesh filename="package://rx1_description/meshes/leap_hand/left_pip.stl"/>
      </geometry>
      <material name="left_index_pip_material">
        <color rgba="0.74901960784313725839 0.74901960784313725839 0.74901960784313725839 1.0"/>
      </material>
    </visual>
    <collision>
      <origin rpy="-1.570796326794896558 -1.570796326794896336 0" xyz="0.0096433630922713314826 0.00029999999999999471534 0.00078403401041737472155"/>
      <geometry>
        <mesh filename="package://rx1_description/meshes/leap_hand/left_pip.stl"/>
      </geometry>
    </collision>
    <inertial>
      <origin rpy="0 0 0" xyz="0 0 0"/>
      <mass value="0.032"/>
      <inertia ixx="0.000004798" ixy="0.000000012" ixz="0.000000004" iyy="0.000002862" iyz="0.000000011" izz="0.000004234"/>
    </inertial>
  </link>
  <link name="left_index_dip_link">
    <visual>
      <origin rpy="-3.141592653589793116 4.5075111242164408299e-32 4.4395481053923607589e-32" xyz="0.021133352895225002849 -0.0084321191467048722812 0.0097850881620952234741"/>
      <geometry>
        <mesh filename="package://rx1_description/meshes/leap_hand/left_dip.stl"/>
      </geometry>
      <material name="left_index_dip_material">
        <color rgba="0.86666666666666669627 0.86666666666666669627 0.050980392156862744391 1.0"/>
      </material>
    </visual>
    <collision>
      <origin rpy="-3.141592653589793116 4.5075111242164408299e-32 4.4395481053923607589e-32" xyz="0.021133352895225002849 -0.0084321191467048722812 0.0097850881620952234741"/>
      <geometry>
        <mesh filename="package://rx1_description/meshes/leap_hand/left_dip.stl"/>
      </geometry>
    </collision>
    <inertial>
      <origin rpy="0 0 0" xyz="0 0 0"/>
      <mass value="0.037"/>
      <inertia ixx="0.000005542" ixy="-0.000000607" ixz="-0.000000017" iyy="0.000005727" iyz="-0.000000023" izz="0.000006682"/>
    </inertial>
  </link>
  <link name="left_index_fingertip">
    <visual>
      <origin rpy="3.141592653589793116 1.1993117970061734707e-33 4.4395481053923607589e-32" xyz="0.013286424108533503169 -0.00611423838654200167 0.014499999999999513278"/>
      <geometry>
        <mesh filename="package://rx1_description/meshes/leap_hand/left_fingertip.stl"/>
      </geometry>
      <material name="left_index_fingertip_material">
        <color rgba="0.86666666666666669627 0.86666666666666669627 0.050980392156862744391 1.0"/>
      </material>
    </visual>
    <collision>
      <origin rpy="3.141592653589793116 1.1993117970061734707e-33 4.4395481053923607589e-32" xyz="0.013286424108533503169 -0.00611423838654200167 0.014499999999999513278"/>
      <geometry>
        <mesh filename="package://rx1_description/meshes/leap_hand/left_fingertip.stl"/>
      </geometry>
    </collision>
    <inertial>
      <origin rpy="0 0 0" xyz="0 0 0"/>
      <mass value="0.016"/>
      <inertia ixx="0.000003368" ixy="0.000000115" ixz="0" iyy="0.000001556" iyz="0" izz="0.000002863"/>
    </inertial>
  </link>
  <!-- Index finger joints -->
  <joint name="left_index_joint_mcp_to_pip" type="revolute">
    <origin rpy="-1.57079632679489678 2.8029314871654157891e-15 1.570796326794896336" xyz="-0.012200000000000005979 0.038100000000000001921 0.014499999999999985123"/>
    <parent link="left_index_mcp_link"/>
    <child link="left_index_pip_link"/>
    <axis xyz="0 0 -1"/>
    <limit effort="0.95" lower="-1.047" upper="1.047" velocity="8.48"/>
  </joint>
  <joint name="left_index_joint_palm_to_mcp" type="revolute">
    <origin rpy="1.5707963267948987784 1.570796326794896558 0" xyz="-0.082574224938392518092 -0.085740011501137525229 0.0078008885838987494094"/>
    <parent link="left_palm_lower"/>
    <child link="left_index_mcp_link"/>
    <axis xyz="0 0 -1"/>
    <limit effort="0.95" lower="-0.314" upper="2.23" velocity="8.48"/>
  </joint>
  <joint name="left_index_joint_pip_to_dip" type="revolute">
    <origin rpy="1.5707963267948958919 -1.570796326794896336 0" xyz="0.014999999999999961281 0.014299999999999993272 -0.013000000000000025424"/>
    <parent link="left_index_pip_link"/>
    <child link="left_index_dip_link"/>
    <axis xyz="0 0 -1"/>
    <limit effort="0.95" lower="-0.506" upper="1.885" velocity="8.48"/>
  </joint>
  <joint name="left_index_joint_dip_to_fingertip" type="revolute">
    <origin rpy="4.5935029425113685044e-17 -2.8730071914463794583e-16 4.4395481053923607589e-32" xyz="-4.0880582469551840497e-09 -0.03610000421036734658 0.0002000000000000612399"/>
    <parent link="left_index_dip_link"/>
    <child link="left_index_fingertip"/>
    <axis xyz="0 0 -1"/>
    <limit effort="0.95" lower="-0.366" upper="2.042" velocity="8.48"/>
  </joint>
  <!-- Middle finger chain -->
  <link name="left_middle_mcp_link">
    <visual>
      <origin rpy="1.6375789613220997835e-15 -1.0045650589925207743e-30 -1.2404717968013979433e-44" xyz="0.008406902261174501248 0.0077662438597169841659 0.014657354985032906847"/>
      <geometry>
        <mesh filename="package://rx1_description/meshes/leap_hand/left_mcp_joint.stl"/>
      </geometry>
      <material name="left_middle_mcp_material">
        <color rgba="0.86666666666666669627 0.86666666666666669627 0.050980392156862744391 1.0"/>
      </material>
    </visual>
    <collision>
      <origin rpy="1.6375789613220997835e-15 -1.0045650589925207743e-30 -1.2404717968013979433e-44" xyz="0.008406902261174501248 0.0077662438597169841659 0.014657354985032906847"/>
      <geometry>
        <mesh filename="package://rx1_description/meshes/leap_hand/left_mcp_joint.stl"/>
      </geometry>
    </collision>
    <inertial>
      <origin rpy="0 0 0" xyz="0 0 0"/>
      <mass value="0.044"/>
      <inertia ixx="0.000011499" ixy="0.000003049" ixz="0.000000121" iyy="0.000007796" iyz="0.000000112" izz="0.000014759"/>
    </inertial>
  </link>
  <link name="left_middle_pip_link">
    <visual>
      <origin rpy="-1.570796326794896558 -1.570796326794896336 0" xyz="0.0096433630922713314826 0.00029999999999998777644 0.00078403401041737472155"/>
      <geometry>
        <mesh filename="package://rx1_description/meshes/leap_hand/left_pip.stl"/>
      </geometry>
      <material name="left_middle_pip_material">
        <color rgba="0.74901960784313725839 0.74901960784313725839 0.74901960784313725839 1.0"/>
      </material>
    </visual>
    <collision>
      <origin rpy="-1.570796326794896558 -1.570796326794896336 0" xyz="0.0096433630922713314826 0.00029999999999998777644 0.00078403401041737472155"/>
      <geometry>
        <mesh filename="package://rx1_description/meshes/leap_hand/left_pip.stl"/>
      </geometry>
    </collision>
    <inertial>
      <origin rpy="0 0 0" xyz="0 0 0"/>
      <mass value="0.032"/>
      <inertia ixx="0.000004798" ixy="0.000000012" ixz="0.000000004" iyy="0.000002862" iyz="0.000000011" izz="0.000004234"/>
    </inertial>
  </link>
  <link name="left_middle_dip_link">
    <visual>
      <origin rpy="-3.141592653589793116 2.1146933785271955805e-32 1.4408183216511868558e-31" xyz="0.021133352895225002849 -0.0084321191467048722812 0.0097850881620952373519"/>
      <geometry>
        <mesh filename="package://rx1_description/meshes/leap_hand/left_dip.stl"/>
      </geometry>
      <material name="left_middle_dip_material">
        <color rgba="0.86666666666666669627 0.86666666666666669627 0.050980392156862744391 1.0"/>
      </material>
    </visual>
    <collision>
      <origin rpy="-3.141592653589793116 2.1146933785271955805e-32 1.4408183216511868558e-31" xyz="0.021133352895225002849 -0.0084321191467048722812 0.0097850881620952373519"/>
      <geometry>
        <mesh filename="package://rx1_description/meshes/leap_hand/left_dip.stl"/>
      </geometry>
    </collision>
    <inertial>
      <origin rpy="0 0 0" xyz="0 0 0"/>
      <mass value="0.037"/>
      <inertia ixx="0.000005542" ixy="-0.000000607" ixz="-0.000000017" iyy="0.000005727" iyz="-0.000000023" izz="0.000006682"/>
    </inertial>
  </link>
  <link name="left_middle_fingertip">
    <visual>
      <origin rpy="3.141592653589793116 -4.3179597882835943107e-33 1.4408183216511868558e-31" xyz="0.01328642410853349623 -0.0061142383865420008027 0.014499999999999495931"/>
      <geometry>
        <mesh filename="package://rx1_description/meshes/leap_hand/right_fingertip.stl"/>
        <!-- Mesh filename remains unchanged -->
      </geometry>
      <material name="left_middle_fingertip_material">
        <color rgba="0.86666666666666669627 0.86666666666666669627 0.050980392156862744391 1.0"/>
      </material>
    </visual>
    <collision>
      <origin rpy="3.141592653589793116 -4.3179597882835943107e-33 1.4408183216511868558e-31" xyz="0.01328642410853349623 -0.0061142383865420008027 0.014499999999999495931"/>
      <geometry>
        <mesh filename="package://rx1_description/meshes/leap_hand/right_fingertip.stl"/>
      </geometry>
    </collision>
    <inertial>
      <origin rpy="0 0 0" xyz="0 0 0"/>
      <mass value="0.016"/>
      <inertia ixx="0.000003368" ixy="0.000000115" ixz="0" iyy="0.000001556" iyz="0" izz="0.000002863"/>
    </inertial>
  </link>
  <!-- Middle finger joints -->
  <joint name="left_middle_joint_mcp_to_pip" type="revolute">
    <origin rpy="-1.570796326794896558 1.6094417208041279902e-15 1.5707963267948943376" xyz="-0.012200000000000002509 0.038099999999999988043 0.014499999999999999001"/>
    <parent link="left_middle_mcp_link"/>
    <child link="left_middle_pip_link"/>
    <axis xyz="0 0 -1"/>
    <limit effort="0.95" lower="-1.047" upper="1.047" velocity="8.48"/>
  </joint>
  <joint name="left_middle_joint_palm_to_mcp" type="revolute">
    <origin rpy="1.5707963267948992225 1.570796326794896558 0" xyz="-0.08257422493900856697 -0.040290011501137479311 0.007800888583679612201"/>
    <parent link="left_palm_lower"/>
    <child link="left_middle_mcp_link"/>
    <axis xyz="0 0 -1"/>
    <limit effort="0.95" lower="-0.314" upper="2.23" velocity="8.48"/>
  </joint>
  <joint name="left_middle_joint_pip_to_dip" type="revolute">
    <origin rpy="1.5707963267948958919 -1.570796326794896336 0" xyz="0.01499999999999996475 0.014299999999999986333 -0.013000000000000025424"/>
    <parent link="left_middle_pip_link"/>
    <child link="left_middle_dip_link"/>
    <axis xyz="0 0 -1"/>
    <limit effort="0.95" lower="-0.506" upper="1.885" velocity="8.48"/>
  </joint>
  <joint name="left_middle_joint_dip_to_fingertip" type="revolute">
    <origin rpy="4.5935029425113654229e-17 -2.8730071914463794583e-16 1.4408183216511868558e-31" xyz="1.0408340855860842566e-16 -0.036099999999999875244 0.00020000000000007511769"/>
    <parent link="left_middle_dip_link"/>
    <child link="left_middle_fingertip"/>
    <axis xyz="0 0 -1"/>
    <limit effort="0.95" lower="-0.366" upper="2.042" velocity="8.48"/>
  </joint>
  <!-- Ring finger chain -->
  <link name="left_ring_mcp_link">
    <visual>
      <origin rpy="1.6375789613220999807e-15 -1.0045650589924056927e-30 -1.6748666234615871922e-44" xyz="0.008406902261174501248 0.0077662438597169980437 0.014657354985032912051"/>
      <geometry>
        <mesh filename="package://rx1_description/meshes/leap_hand/left_mcp_joint.stl"/>
      </geometry>
      <material name="left_ring_mcp_material">
        <color rgba="0.86666666666666669627 0.86666666666666669627 0.050980392156862744391 1.0"/>
      </material>
    </visual>
    <collision>
      <origin rpy="1.6375789613220999807e-15 -1.0045650589924056927e-30 -1.6748666234615871922e-44" xyz="0.008406902261174501248 0.0077662438597169980437 0.014657354985032912051"/>
      <geometry>
        <mesh filename="package://rx1_description/meshes/leap_hand/left_mcp_joint.stl"/>
      </geometry>
    </collision>
    <inertial>
      <origin rpy="0 0 0" xyz="0 0 0"/>
      <mass value="0.044"/>
      <inertia ixx="0.000011499" ixy="0.000003049" ixz="0.000000121" iyy="0.000007796" iyz="0.000000112" izz="0.000014759"/>
    </inertial>
  </link>
  <link name="left_ring_pip_link">
    <visual>
      <origin rpy="-1.570796326794896558 -1.570796326794896336 0" xyz="0.0096433630922713314826 0.00029999999999998083755 0.00078403401041737472155"/>
      <geometry>
        <mesh filename="package://rx1_description/meshes/leap_hand/left_pip.stl"/>
      </geometry>
      <material name="left_ring_pip_material">
        <color rgba="0.74901960784313725839 0.74901960784313725839 0.74901960784313725839 1.0"/>
      </material>
    </visual>
    <collision>
      <origin rpy="-1.570796326794896558 -1.570796326794896336 0" xyz="0.0096433630922713314826 0.00029999999999998083755 0.00078403401041737472155"/>
      <geometry>
        <mesh filename="package://rx1_description/meshes/leap_hand/left_pip.stl"/>
      </geometry>
    </collision>
    <inertial>
      <origin rpy="0 0 0" xyz="0 0 0"/>
      <mass value="0.032"/>
      <inertia ixx="0.000004798" ixy="0.000000012" ixz="0.000000004" iyy="0.000002862" iyz="0.000000011" izz="0.000004234"/>
    </inertial>
  </link>
  <link name="left_ring_dip_link">
    <visual>
      <origin rpy="-3.141592653589793116 -1.4095651113919093005e-33 1.5565411607615035382e-32" xyz="0.021133352895225006318 -0.0084321191467048688117 0.0097850881620952408213"/>
      <geometry>
        <mesh filename="package://rx1_description/meshes/leap_hand/left_dip.stl"/>
      </geometry>
      <material name="left_ring_dip_material">
        <color rgba="0.86666666666666669627 0.86666666666666669627 0.050980392156862744391 1.0"/>
      </material>
    </visual>
    <collision>
      <origin rpy="-3.141592653589793116 -1.4095651113919093005e-33 1.5565411607615035382e-32" xyz="0.021133352895225006318 -0.0084321191467048688117 0.0097850881620952408213"/>
      <geometry>
        <mesh filename="package://rx1_description/meshes/leap_hand/left_dip.stl"/>
      </geometry>
    </collision>
    <inertial>
      <origin rpy="0 0 0" xyz="0 0 0"/>
      <mass value="0.037"/>
      <inertia ixx="0.000005542" ixy="-0.000000607" ixz="-0.000000017" iyy="0.000005727" iyz="-0.000000023" izz="0.000006682"/>
    </inertial>
  </link>
  <link name="left_ring_fingertip">
    <visual>
      <origin rpy="3.141592653589793116 8.6170716950575402125e-33 1.5565411607615035382e-32" xyz="0.013286424108533499699 -0.00611423838654200167 0.014499999999999495931"/>
      <geometry>
        <mesh filename="package://rx1_description/meshes/leap_hand/left_fingertip.stl"/>
      </geometry>
      <material name="left_ring_fingertip_material">
        <color rgba="0.86666666666666669627 0.86666666666666669627 0.050980392156862744391 1.0"/>
      </material>
    </visual>
    <collision>
      <origin rpy="3.141592653589793116 8.6170716950575402125e-33 1.5565411607615035382e-32" xyz="0.013286424108533499699 -0.00611423838654200167 0.014499999999999495931"/>
      <geometry>
        <mesh filename="package://rx1_description/meshes/leap_hand/left_fingertip.stl"/>
      </geometry>
    </collision>
    <inertial>
      <origin rpy="0 0 0" xyz="0 0 0"/>
      <mass value="0.016"/>
      <inertia ixx="0.000003368" ixy="0.000000115" ixz="0" iyy="0.000001556" iyz="0" izz="0.000002863"/>
    </inertial>
  </link>
  <!-- Ring finger joints -->
  <joint name="left_ring_joint_mcp_to_pip" type="revolute">
    <origin rpy="-1.57079632679489678 2.8029314871654240721e-15 1.570796326794896336" xyz="-0.012200000000000002509 0.038100000000000001921 0.01450000000000000247"/>
    <parent link="left_ring_mcp_link"/>
    <child link="left_ring_pip_link"/>
    <axis xyz="0 0 -1"/>
    <limit effort="0.95" lower="-1.047" upper="1.047" velocity="8.48"/>
  </joint>
  <joint name="left_ring_joint_palm_to_mcp" type="revolute">
    <origin rpy="1.5707963267948987784 1.570796326794896558 0" xyz="-0.082574224938392323803 0.0051599884988625839555 0.0078008885838987598177"/>
    <parent link="left_palm_lower"/>
    <child link="left_ring_mcp_link"/>
    <axis xyz="0 0 -1"/>
    <limit effort="0.95" lower="-0.314" upper="2.23" velocity="8.48"/>
  </joint>
  <joint name="left_ring_joint_pip_to_dip" type="revolute">
    <origin rpy="1.5707963267948958919 -1.570796326794896336 0" xyz="0.01499999999999996822 0.014299999999999989803 -0.013000000000000025424"/>
    <parent link="left_ring_pip_link"/>
    <child link="left_ring_dip_link"/>
    <axis xyz="0 0 -1"/>
    <limit effort="0.95" lower="-0.506" upper="1.885" velocity="8.48"/>
  </joint>
  <joint name="left_ring_joint_dip_to_fingertip" type="revolute">
    <origin rpy="4.5935029425113685044e-17 -2.8730071914463794583e-16 1.5565411607615035382e-32" xyz="1.0234868508263161857e-16 -0.036099999999999868305 0.00020000000000007858714"/>
    <parent link="left_ring_dip_link"/>
    <child link="left_ring_fingertip"/>
    <axis xyz="0 0 -1"/>
    <limit effort="0.95" lower="-0.366" upper="2.042" velocity="8.48"/>
  </joint>
  <!-- Thumb chain -->
  <link name="left_thumb_base">
    <visual>
      <origin rpy="1.570796326794896558 -7.3390819752428127848e-33 -2.4651903288114908395e-32" xyz="0.043932212010113096123 0.0068107072931437306895 0.021460907869434775463"/>
      <geometry>
        <mesh filename="package://rx1_description/meshes/leap_hand/left_thumb_left_temp_base.stl"/>
      </geometry>
      <material name="left_thumb_base_material">
        <color rgba="0.74901960784313725839 0.74901960784313725839 0.74901960784313725839 1.0"/>
      </material>
    </visual>
    <collision>
      <origin rpy="1.570796326794896558 -7.3390819752428127848e-33 -2.4651903288114908395e-32" xyz="0.043932212010113096123 0.0068107072931437306895 0.021460907869434775463"/>
      <geometry>
        <mesh filename="package://rx1_description/meshes/leap_hand/left_thumb_left_temp_base.stl"/>
      </geometry>
    </collision>
    <inertial>
      <origin rpy="0 0 0" xyz="0 0 0"/>
      <mass value="0.032"/>
      <inertia ixx="0.000004798" ixy="0.000000012" ixz="0.000000004" iyy="0.000002862" iyz="0.000000011" izz="0.000004234"/>
    </inertial>
  </link>
  <link name="left_thumb_pip_link">
    <visual>
      <origin rpy="1.570796326794896558 1.6544612350564779759e-32 0" xyz="0.011961920770611200737 -5.3169274538689137444e-16 -0.015852648956664189273"/>
      <geometry>
        <mesh filename="package://rx1_description/meshes/leap_hand/left_thumb_pip.stl"/>
      </geometry>
      <material name="left_thumb_pip_material">
        <color rgba="0.86666666666666669627 0.86666666666666669627 0.050980392156862744391 1.0"/>
      </material>
    </visual>
    <collision>
      <origin rpy="1.570796326794896558 1.6544612350564779759e-32 0" xyz="0.011961920770611200737 -5.3169274538689137444e-16 -0.015852648956664189273"/>
      <geometry>
        <mesh filename="package://rx1_description/meshes/leap_hand/left_thumb_pip.stl"/>
      </geometry>
    </collision>
    <inertial>
      <origin rpy="0 0 0" xyz="0 0 0"/>
      <mass value="0.003"/>
      <inertia ixx="0.000000593" ixy="0" ixz="0" iyy="0.000000549" iyz="0" izz="0.000000224"/>
    </inertial>
  </link>
  <link name="left_thumb_dip_link">
    <visual>
      <origin rpy="1.9428902930940096476e-16 3.2751579226442204717e-15 -2.172448977268026949e-31" xyz="0.043968715707239161561 0.057952952973709212503 -0.0086286764493694757122"/>
      <geometry>
        <mesh filename="package://rx1_description/meshes/leap_hand/left_thumb_dip.stl"/>
      </geometry>
      <material name="left_thumb_dip_material">
        <color rgba="0.86666666666666669627 0.86666666666666669627 0.050980392156862744391 1.0"/>
      </material>
    </visual>
    <collision>
      <origin rpy="1.9428902930940096476e-16 3.2751579226442204717e-15 -2.172448977268026949e-31" xyz="0.043968715707239161561 0.057952952973709212503 -0.0086286764493694757122"/>
      <geometry>
        <mesh filename="package://rx1_description/meshes/leap_hand/left_thumb_dip.stl"/>
      </geometry>
    </collision>
    <inertial>
      <origin rpy="0 0 0" xyz="0 0 0"/>
      <mass value="0.038"/>
      <inertia ixx="0.000008474" ixy="0.000000241" ixz="0.000000026" iyy="0.000003841" iyz="0.000000025" izz="0.000007679"/>
    </inertial>
  </link>
  <link name="left_thumb_fingertip">
    <visual>
      <origin rpy="2.586996940753466404e-33 -3.3306690738754701143e-16 4.6050499879454267902e-33" xyz="0.062559538462667402259 0.078459682911396960714 0.048992911807332208129"/>
      <geometry>
        <mesh filename="package://rx1_description/meshes/leap_hand/left_thumb_fingertip.stl"/>
      </geometry>
      <material name="left_thumb_fingertip_material">
        <color rgba="0.60392156862745094426 0.14901960784313725283 0.14901960784313725283 1.0"/>
      </material>
    </visual>
    <collision>
      <origin rpy="2.586996940753466404e-33 -3.3306690738754701143e-16 4.6050499879454267902e-33" xyz="0.062559538462667402259 0.078459682911396960714 0.048992911807332208129"/>
      <geometry>
        <mesh filename="package://rx1_description/meshes/leap_hand/left_thumb_fingertip.stl"/>
      </geometry>
    </collision>
    <inertial>
      <origin rpy="0 0 0" xyz="0 0 0"/>
      <mass value="0.049"/>
      <inertia ixx="0.000020372" ixy="-0.000000489" ixz="-0.00000003" iyy="0.000004336" iyz="-0.000000097" izz="0.000019845"/>
    </inertial>
  </link>
  <!-- Thumb joints -->
  <joint name="left_thumb_joint_base_to_pip" type="revolute">
    <origin rpy="-1.570796326794896336 -1.570796326794896336 0" xyz="-1.0148132334464321502e-16 -0.014100000000000126321 -0.012999999999999956035"/>
    <parent link="left_thumb_base"/>
    <child link="left_thumb_pip_link"/>
    <axis xyz="0 0 -1"/>
    <limit effort="0.95" lower="-2.094" upper="0.349" velocity="8.48"/>
  </joint>
  <joint name="left_thumb_joint_palm_to_base" type="revolute">
    <origin rpy="3.5629789726327258012e-15 1.5707963267948961139 0" xyz="-0.14487422493839263726 -0.090040011501137440231 0.004900888583899039308"/>
    <parent link="left_palm_lower"/>
    <child link="left_thumb_base"/>
    <axis xyz="0 0 -1"/>
    <limit effort="0.95" lower="-2.443" upper="0.47" velocity="8.48"/>
  </joint>
  <joint name="left_thumb_joint_pip_to_dip" type="revolute">
    <origin rpy="-1.570796326794896558 -1.5671206742950610653e-15 -5.6898930012051145053e-16" xyz="0 0.014499999999999967776 -0.017000000000000042855"/>
    <parent link="left_thumb_pip_link"/>
    <child link="left_thumb_dip_link"/>
    <axis xyz="0 0 -1"/>
    <limit effort="0.95" lower="-1.20" upper="1.90" velocity="8.48"/>
  </joint>
  <joint name="left_thumb_joint_dip_to_fingertip" type="revolute">
    <origin rpy="-3.1092019091748562186e-17 -4.9644253794601335075e-16 -3.1415926535897846783" xyz="-1.1102230246251565404e-16 0.046599999999999683342 0.00020000000000065451533"/>
    <parent link="left_thumb_dip_link"/>
    <child link="left_thumb_fingertip"/>
    <axis xyz="0 0 -1"/>
    <limit effort="0.95" lower="-1.34" upper="1.88" velocity="8.48"/>
  </joint>
  <!-- Connect to the already defined hand -->
  <joint name="left_forearm_roll2palm_joint" type="fixed">
    <origin rpy="0 1.57075 0" xyz="0 0.05 -0.22"/>
    <parent link="left_forearm_roll_link"/>
    <child link="left_palm_lower"/>
  </joint>
  <!--                            ARM END                             -->
</robot>

